Traceback (most recent call last):
  File "C:\Users\kamil\AppData\Roaming\Python\Python39\site-packages\jupyter_cache\executors\utils.py", line 58, in single_nb_execution
    executenb(
  File "C:\ProgramData\Anaconda3\lib\site-packages\nbclient\client.py", line 1204, in execute
    return NotebookClient(nb=nb, resources=resources, km=km, **kwargs).execute()
  File "C:\ProgramData\Anaconda3\lib\site-packages\nbclient\util.py", line 84, in wrapped
    return just_run(coro(*args, **kwargs))
  File "C:\ProgramData\Anaconda3\lib\site-packages\nbclient\util.py", line 62, in just_run
    return loop.run_until_complete(coro)
  File "C:\ProgramData\Anaconda3\lib\asyncio\base_events.py", line 647, in run_until_complete
    return future.result()
  File "C:\ProgramData\Anaconda3\lib\site-packages\nbclient\client.py", line 663, in async_execute
    await self.async_execute_cell(
  File "C:\ProgramData\Anaconda3\lib\site-packages\nbclient\client.py", line 965, in async_execute_cell
    await self._check_raise_for_error(cell, cell_index, exec_reply)
  File "C:\ProgramData\Anaconda3\lib\site-packages\nbclient\client.py", line 862, in _check_raise_for_error
    raise CellExecutionError.from_cell_and_msg(cell, exec_reply_content)
nbclient.exceptions.CellExecutionError: An error occurred while executing the following cell:
------------------
Image("D:\\Szkolenie_Python\\Wyklad1\\anaconda.PNG")
------------------

[1;31m---------------------------------------------------------------------------[0m
[1;31mNameError[0m                                 Traceback (most recent call last)
Input [1;32mIn [1][0m, in [0;36m<cell line: 1>[1;34m()[0m
[1;32m----> 1[0m [43mImage[49m([38;5;124m"[39m[38;5;124mD:[39m[38;5;130;01m\\[39;00m[38;5;124mSzkolenie_Python[39m[38;5;130;01m\\[39;00m[38;5;124mWyklad1[39m[38;5;130;01m\\[39;00m[38;5;124manaconda.PNG[39m[38;5;124m"[39m)

[1;31mNameError[0m: name 'Image' is not defined
NameError: name 'Image' is not defined

